(.venv) pi@raspberrypi:~/apps $ /home/pi/apps/manager_server/.venv/bin/python3.11 /home/pi/apps/manager_server/manager_node/main.py
logger started
Xgboost model started
SSH connect started
======== Running on http://0.0.0.0:8199 ========
(Press CTRL+C to quit)
Future exception was never retrieved
future: <Future finished exception=TypeError("cannot pickle '_asyncio.Future' object")>
concurrent.futures.process._RemoteTraceback: 
"""
Traceback (most recent call last):
  File "/usr/lib/python3.11/multiprocessing/queues.py", line 244, in _feed
    obj = _ForkingPickler.dumps(obj)
          ^^^^^^^^^^^^^^^^^^^^^^^^^^
  File "/usr/lib/python3.11/multiprocessing/reduction.py", line 51, in dumps
    cls(buf, protocol).dump(obj)
TypeError: cannot pickle '_asyncio.Future' object
"""

The above exception was the direct cause of the following exception:

Traceback (most recent call last):
  File "/usr/lib/python3.11/multiprocessing/queues.py", line 244, in _feed
    obj = _ForkingPickler.dumps(obj)
          ^^^^^^^^^^^^^^^^^^^^^^^^^^
  File "/usr/lib/python3.11/multiprocessing/reduction.py", line 51, in dumps
    cls(buf, protocol).dump(obj)
TypeError: cannot pickle '_asyncio.Future' object
Future exception was never retrieved
future: <Future finished exception=AttributeError("Can't pickle local object '_chain_future.<locals>._set_state'")>
concurrent.futures.process._RemoteTraceback: 
"""
Traceback (most recent call last):
  File "/usr/lib/python3.11/multiprocessing/queues.py", line 244, in _feed
    obj = _ForkingPickler.dumps(obj)
          ^^^^^^^^^^^^^^^^^^^^^^^^^^
  File "/usr/lib/python3.11/multiprocessing/reduction.py", line 51, in dumps
    cls(buf, protocol).dump(obj)
AttributeError: Can't pickle local object '_chain_future.<locals>._set_state'
"""

The above exception was the direct cause of the following exception:

Traceback (most recent call last):
  File "/usr/lib/python3.11/multiprocessing/queues.py", line 244, in _feed
    obj = _ForkingPickler.dumps(obj)
          ^^^^^^^^^^^^^^^^^^^^^^^^^^
  File "/usr/lib/python3.11/multiprocessing/reduction.py", line 51, in dumps
    cls(buf, protocol).dump(obj)
AttributeError: Can't pickle local object '_chain_future.<locals>._set_state'
Future exception was never retrieved
future: <Future finished exception=AttributeError("Can't pickle local object '_chain_future.<locals>._set_state'")>
concurrent.futures.process._RemoteTraceback: 
"""
Traceback (most recent call last):
  File "/usr/lib/python3.11/multiprocessing/queues.py", line 244, in _feed
    obj = _ForkingPickler.dumps(obj)
          ^^^^^^^^^^^^^^^^^^^^^^^^^^
  File "/usr/lib/python3.11/multiprocessing/reduction.py", line 51, in dumps
    cls(buf, protocol).dump(obj)
AttributeError: Can't pickle local object '_chain_future.<locals>._set_state'
"""

The above exception was the direct cause of the following exception:

Traceback (most recent call last):
  File "/usr/lib/python3.11/multiprocessing/queues.py", line 244, in _feed
    obj = _ForkingPickler.dumps(obj)
          ^^^^^^^^^^^^^^^^^^^^^^^^^^
  File "/usr/lib/python3.11/multiprocessing/reduction.py", line 51, in dumps
    cls(buf, protocol).dump(obj)
AttributeError: Can't pickle local object '_chain_future.<locals>._set_state'
Future exception was never retrieved
future: <Future finished exception=AttributeError("Can't pickle local object '_chain_future.<locals>._call_check_cancel'")>
concurrent.futures.process._RemoteTraceback: 
"""
Traceback (most recent call last):
  File "/usr/lib/python3.11/multiprocessing/queues.py", line 244, in _feed
    obj = _ForkingPickler.dumps(obj)
          ^^^^^^^^^^^^^^^^^^^^^^^^^^
  File "/usr/lib/python3.11/multiprocessing/reduction.py", line 51, in dumps
    cls(buf, protocol).dump(obj)
AttributeError: Can't pickle local object '_chain_future.<locals>._call_check_cancel'
"""

The above exception was the direct cause of the following exception:

Traceback (most recent call last):
  File "/usr/lib/python3.11/multiprocessing/queues.py", line 244, in _feed
    obj = _ForkingPickler.dumps(obj)
          ^^^^^^^^^^^^^^^^^^^^^^^^^^
  File "/usr/lib/python3.11/multiprocessing/reduction.py", line 51, in dumps
    cls(buf, protocol).dump(obj)
AttributeError: Can't pickle local object '_chain_future.<locals>._call_check_cancel'
Future exception was never retrieved
future: <Future finished exception=AttributeError("Can't pickle local object '_chain_future.<locals>._set_state'")>
concurrent.futures.process._RemoteTraceback: 
"""
Traceback (most recent call last):
  File "/usr/lib/python3.11/multiprocessing/queues.py", line 244, in _feed
    obj = _ForkingPickler.dumps(obj)
          ^^^^^^^^^^^^^^^^^^^^^^^^^^
  File "/usr/lib/python3.11/multiprocessing/reduction.py", line 51, in dumps
    cls(buf, protocol).dump(obj)
AttributeError: Can't pickle local object '_chain_future.<locals>._set_state'
"""

The above exception was the direct cause of the following exception:

Traceback (most recent call last):
  File "/usr/lib/python3.11/multiprocessing/queues.py", line 244, in _feed
    obj = _ForkingPickler.dumps(obj)
          ^^^^^^^^^^^^^^^^^^^^^^^^^^
  File "/usr/lib/python3.11/multiprocessing/reduction.py", line 51, in dumps
    cls(buf, protocol).dump(obj)
AttributeError: Can't pickle local object '_chain_future.<locals>._set_state'
Future exception was never retrieved
future: <Future finished exception=TypeError("cannot pickle '_contextvars.Context' object")>
concurrent.futures.process._RemoteTraceback: 
"""
Traceback (most recent call last):
  File "/usr/lib/python3.11/multiprocessing/queues.py", line 244, in _feed
    obj = _ForkingPickler.dumps(obj)
          ^^^^^^^^^^^^^^^^^^^^^^^^^^
  File "/usr/lib/python3.11/multiprocessing/reduction.py", line 51, in dumps
    cls(buf, protocol).dump(obj)
TypeError: cannot pickle '_contextvars.Context' object
"""

The above exception was the direct cause of the following exception:

Traceback (most recent call last):
  File "/usr/lib/python3.11/multiprocessing/queues.py", line 244, in _feed
    obj = _ForkingPickler.dumps(obj)
          ^^^^^^^^^^^^^^^^^^^^^^^^^^
  File "/usr/lib/python3.11/multiprocessing/reduction.py", line 51, in dumps
    cls(buf, protocol).dump(obj)
TypeError: cannot pickle '_contextvars.Context' object